Workbook
Name AsOfDate: Assumptions!$B$3
Name PAR1: Assumptions!$B$4
Name PAR2: Assumptions!$B$5

Sheet Assumptions
A1: Assumptions & Snapshot Date
A3: Portfolio snapshot (as-of) date | B3: 46266
A4: PAR threshold 1 (days) | B4: 30
A5: PAR threshold 2 (days) | B5: 90
A7: Blue = input cell you can change. All PAR/repayment calculations recompute automatically.

Sheet Data - Borrowers
A1: borrower_id | B1: sector | C1: region | D1: registration_date | E1: business_age_months | F1: monthly_revenue_kes | G1: num_employees | H1: gender_of_owner | I1: bureau_score
A2: BOR100000 | B2: Retail & Trade | C2: Rural - Other | D2: 43787 | E2: 95 | F2: 80000 | G2: 8 | H2: Male | I2: 668
A3: BOR100001 | B3: Transport & Logistics | C3: Nairobi | D3: 43908 | E3: 48 | F3: 388800 | G3: 10 | H3: Male | I3: 580
A4: BOR100002 | B4: Services | C4: Rural - Other | D4: 42798 | E4: 33 | F4: 33900 | G4: 12 | H4: Female | I4: 555
A5: BOR100003 | B5: Manufacturing | C5: Nairobi | D5: 44319 | E5: 30 | F5: 68100 | G5: 1 | H5: Male | I5: 582
A6: BOR100004 | B6: Manufacturing | C6: Rural - Other | D6: 45184 | E6: 142 | F6: 257500 | G6: 18 | H6: Male | I6: 486
A7: BOR100005 | B7: Construction | C7: Rural - Other | D7: 43144 | E7: 17 | F7: 168400 | G7: 3 | H7: Female | I7: 636
A8: BOR100006 | B8: Retail & Trade | C8: Rural - Other | D8: 46123 | E8: 116 | F8: 44900 | G8: 12 | H8: Male | I8: 439
A9: BOR100007 | B9: Transport & Logistics | C9: Eldoret | D9: 44614 | E9: 125 | F9: 85500 | G9: 16 | H9: Female | I9: 560
A10: BOR100008 | B10: Agriculture | C10: Rural - Other | D10: 45299 | E10: 7 | F10: 73200 | G10: 2 | H10: Male | I10: 668
A11: BOR100009 | B11: Retail & Trade | C11: Nairobi | D11: 42303 | E11: 86 | F11: 89100 | G11: 24 | H11: Female | I11: 627
A12: BOR100010 | B12: Services | C12: Nairobi | D12: 45275 | E12: 84 | F12: 44800 | G12: 10 | H12: Male | I12: 653
A13: BOR100011 | B13: Construction | C13: Nairobi | D13: 43439 | E13: 53 | F13: 68700 | G13: 1 | H13: Male | I13: 594
... A851: BOR100849 | B851: Services | C851: Nairobi | D851: 43416 | E851: 105 | F851: 137800 | G851: 15 | H851: Female | I851: 595

Sheet Data - Loans
A1: loan_id | B1: borrower_id | C1: disbursement_date | D1: loan_amount_kes | E1: loan_term_months | F1: interest_rate | G1: product_type | H1: loan_officer_id | I1: disbursement_channel | J1: sector | K1: region | L1: loan_size_band | M1: disb_month
A2: LN200001 | B2: BOR100000 | C2: 45702 | D2: 78000 | E2: 12 | F2: 0.199 | G2: Working Capital | H2: LO023 | I2: Mobile App | J2: =INDEX('Data - Borrowers'!$B$2:$B$851, MATCH(B2, 'Data - Borrowers'!$A$2:$A$851, 0)) | K2: =INDEX('Data - Borrowers'!$C$2:$C$851, MATCH(B2, 'Data - Borrowers'!$A$2:$A$851, 0)) | L2: =IF(D2<100000, "Micro (<100K)", IF(D2<500000, "Small (100K-500K)", "Medium (500K+)")) | M2: =TEXT(C2, "yyyy-mm")
A3: LN200002 | B3: BOR100000 | C3: 46079 | D3: 41000 | E3: 3 | F3: 0.159 | G3: Working Capital | H3: LO014 | I3: Mobile App | J3: =INDEX('Data - Borrowers'!$B$2:$B$851, MATCH(B3, 'Data - Borrowers'!$A$2:$A$851, 0)) | K3: =INDEX('Data - Borrowers'!$C$2:$C$851, MATCH(B3, 'Data - Borrowers'!$A$2:$A$851, 0)) | L3: =IF(D3<100000, "Micro (<100K)", IF(D3<500000, "Small (100K-500K)", "Medium (500K+)")) | M3: =TEXT(C3, "yyyy-mm")
A4: LN200003 | B4: BOR100001 | C4: 45998 | D4: 277000 | E4: 18 | F4: 0.17 | G4: Invoice Discounting | H4: LO016 | I4: Branch | J4: =INDEX('Data - Borrowers'!$B$2:$B$851, MATCH(B4, 'Data - Borrowers'!$A$2:$A$851, 0)) | K4: =INDEX('Data - Borrowers'!$C$2:$C$851, MATCH(B4, 'Data - Borrowers'!$A$2:$A$851, 0)) | L4: =IF(D4<100000, "Micro (<100K)", IF(D4<500000, "Small (100K-500K)", "Medium (500K+)")) | M4: =TEXT(C4, "yyyy-mm")
A5: LN200004 | B5: BOR100002 | C5: 46033 | D5: 36000 | E5: 3 | F5: 0.206 | G5: Asset Finance | H5: LO021 | I5: Partner Referral | J5: =INDEX('Data - Borrowers'!$B$2:$B$851, MATCH(B5, 'Data - Borrowers'!$A$2:$A$851, 0)) | K5: =INDEX('Data - Borrowers'!$C$2:$C$851, MATCH(B5, 'Data - Borrowers'!$A$2:$A$851, 0)) | L5: =IF(D5<100000, "Micro (<100K)", IF(D5<500000, "Small (100K-500K)", "Medium (500K+)")) | M5: =TEXT(C5, "yyyy-mm")
A6: LN200005 | B6: BOR100003 | C6: 46019 | D6: 56000 | E6: 3 | F6: 0.121 | G6: Working Capital | H6: LO001 | I6: Branch | J6: =INDEX('Data - Borrowers'!$B$2:$B$851, MATCH(B6, 'Data - Borrowers'!$A$2:$A$851, 0)) | K6: =INDEX('Data - Borrowers'!$C$2:$C$851, MATCH(B6, 'Data - Borrowers'!$A$2:$A$851, 0)) | L6: =IF(D6<100000, "Micro (<100K)", IF(D6<500000, "Small (100K-500K)", "Medium (500K+)")) | M6: =TEXT(C6, "yyyy-mm")
A7: LN200006 | B7: BOR100004 | C7: 45949 | D7: 424000 | E7: 3 | F7: 0.127 | G7: Working Capital | H7: LO004 | I7: Mobile App | J7: =INDEX('Data - Borrowers'!$B$2:$B$851, MATCH(B7, 'Data - Borrowers'!$A$2:$A$851, 0)) | K7: =INDEX('Data - Borrowers'!$C$2:$C$851, MATCH(B7, 'Data - Borrowers'!$A$2:$A$851, 0)) | L7: =IF(D7<100000, "Micro (<100K)", IF(D7<500000, "Small (100K-500K)", "Medium (500K+)")) | M7: =TEXT(C7, "yyyy-mm")
A8: LN200007 | B8: BOR100005 | C8: 46158 | D8: 258000 | E8: 9 | F8: 0.202 | G8: Invoice Discounting | H8: LO019 | I8: Branch | J8: =INDEX('Data - Borrowers'!$B$2:$B$851, MATCH(B8, 'Data - Borrowers'!$A$2:$A$851, 0)) | K8: =INDEX('Data - Borrowers'!$C$2:$C$851, MATCH(B8, 'Data - Borrowers'!$A$2:$A$851, 0)) | L8: =IF(D8<100000, "Micro (<100K)", IF(D8<500000, "Small (100K-500K)", "Medium (500K+)")) | M8: =TEXT(C8, "yyyy-mm")
A9: LN200008 | B9: BOR100006 | C9: 45728 | D9: 49000 | E9: 6 | F9: 0.21 | G9: Invoice Discounting | H9: LO006 | I9: Mobile App | J9: =INDEX('Data - Borrowers'!$B$2:$B$851, MATCH(B9, 'Data - Borrowers'!$A$2:$A$851, 0)) | K9: =INDEX('Data - Borrowers'!$C$2:$C$851, MATCH(B9, 'Data - Borrowers'!$A$2:$A$851, 0)) | L9: =IF(D9<100000, "Micro (<100K)", IF(D9<500000, "Small (100K-500K)", "Medium (500K+)")) | M9: =TEXT(C9, "yyyy-mm")
A10: LN200009 | B10: BOR100006 | C10: 46128 | D10: 35000 | E10: 6 | F10: 0.122 | G10: Working Capital | H10: LO005 | I10: Mobile App | J10: =INDEX('Data - Borrowers'!$B$2:$B$851, MATCH(B10, 'Data - Borrowers'!$A$2:$A$851, 0)) | K10: =INDEX('Data - Borrowers'!$C$2:$C$851, MATCH(B10, 'Data - Borrowers'!$A$2:$A$851, 0)) | L10: =IF(D10<100000, "Micro (<100K)", IF(D10<500000, "Small (100K-500K)", "Medium (500K+)")) | M10: =TEXT(C10, "yyyy-mm")
A11: LN200010 | B11: BOR100007 | C11: 45747 | D11: 78000 | E11: 6 | F11: 0.236 | G11: Working Capital | H11: LO002 | I11: Partner Referral | J11: =INDEX('Data - Borrowers'!$B$2:$B$851, MATCH(B11, 'Data - Borrowers'!$A$2:$A$851, 0)) | K11: =INDEX('Data - Borrowers'!$C$2:$C$851, MATCH(B11, 'Data - Borrowers'!$A$2:$A$851, 0)) | L11: =IF(D11<100000, "Micro (<100K)", IF(D11<500000, "Small (100K-500K)", "Medium (500K+)")) | M11: =TEXT(C11, "yyyy-mm")
A12: LN200011 | B12: BOR100007 | C12: 46014 | D12: 48000 | E12: 6 | F12: 0.155 | G12: Working Capital | H12: LO002 | I12: Mobile App | J12: =INDEX('Data - Borrowers'!$B$2:$B$851, MATCH(B12, 'Data - Borrowers'!$A$2:$A$851, 0)) | K12: =INDEX('Data - Borrowers'!$C$2:$C$851, MATCH(B12, 'Data - Borrowers'!$A$2:$A$851, 0)) | L12: =IF(D12<100000, "Micro (<100K)", IF(D12<500000, "Small (100K-500K)", "Medium (500K+)")) | M12: =TEXT(C12, "yyyy-mm")
A13: LN200012 | B13: BOR100008 | C13: 45728 | D13: 96000 | E13: 3 | F13: 0.173 | G13: Working Capital | H13: LO024 | I13: Mobile App | J13: =INDEX('Data - Borrowers'!$B$2:$B$851, MATCH(B13, 'Data - Borrowers'!$A$2:$A$851, 0)) | K13: =INDEX('Data - Borrowers'!$C$2:$C$851, MATCH(B13, 'Data - Borrowers'!$A$2:$A$851, 0)) | L13: =IF(D13<100000, "Micro (<100K)", IF(D13<500000, "Small (100K-500K)", "Medium (500K+)")) | M13: =TEXT(C13, "yyyy-mm")
... A1049: LN201142 | B1049: BOR100849 | C1049: 45723 | D1049: 221000 | E1049: 3 | F1049: 0.227 | G1049: Working Capital | H1049: LO001 | I1049: Partner Referral | J1049: =INDEX('Data - Borrowers'!$B$2:$B$851, MATCH(B1049, 'Data - Borrowers'!$A$2:$A$851, 0)) | K1049: =INDEX('Data - Borrowers'!$C$2:$C$851, MATCH(B1049, 'Data - Borrowers'!$A$2:$A$851, 0)) | L1049: =IF(D1049<100000, "Micro (<100K)", IF(D1049<500000, "Small (100K-500K)", "Medium (500K+)")) | M1049: =TEXT(C1049, "yyyy-mm")

Sheet Data - Repayments
A1: repayment_id | B1: loan_id | C1: installment_no | D1: due_date | E1: due_amount | F1: payment_date | G1: paid_amount | H1: status | I1: dpd_days | J1: pay_month
A2: RP0000001 | B2: LN200001 | C2: 1 | D2: 45730 | E2: 7793.5 | F2: 45727 | G2: 7793.5 | H2: PAID_ON_TIME | I2: =IF(H2="UNPAID", AsOfDate-D2, 0) | J2: =IF(F2<>"", TEXT(F2, "yyyy-mm"), "")
A3: RP0000002 | B3: LN200001 | C3: 2 | D3: 45761 | E3: 7793.5 | F3: 45764 | G3: 7793.5 | H3: PAID_ON_TIME | I3: =IF(H3="UNPAID", AsOfDate-D3, 0) | J3: =IF(F3<>"", TEXT(F3, "yyyy-mm"), "")
A4: RP0000003 | B4: LN200001 | C4: 3 | D4: 45791 | E4: 7793.5 | F4: 45795 | G4: 7793.5 | H4: PAID_ON_TIME | I4: =IF(H4="UNPAID", AsOfDate-D4, 0) | J4: =IF(F4<>"", TEXT(F4, "yyyy-mm"), "")
A5: RP0000004 | B5: LN200001 | C5: 4 | D5: 45822 | E5: 7793.5 | F5: 45824 | G5: 7793.5 | H5: PAID_ON_TIME | I5: =IF(H5="UNPAID", AsOfDate-D5, 0) | J5: =IF(F5<>"", TEXT(F5, "yyyy-mm"), "")
A6: RP0000005 | B6: LN200001 | C6: 5 | D6: 45852 | E6: 7793.5 | F6: 45855 | G6: 7793.5 | H6: PAID_ON_TIME | I6: =IF(H6="UNPAID", AsOfDate-D6, 0) | J6: =IF(F6<>"", TEXT(F6, "yyyy-mm"), "")
A7: RP0000006 | B7: LN200001 | C7: 6 | D7: 45883 | E7: 7793.5 | F7: 45880 | G7: 7793.5 | H7: PAID_ON_TIME | I7: =IF(H7="UNPAID", AsOfDate-D7, 0) | J7: =IF(F7<>"", TEXT(F7, "yyyy-mm"), "")
A8: RP0000007 | B8: LN200001 | C8: 7 | D8: 45914 | E8: 7793.5 | F8: 45917 | G8: 7793.5 | H8: PAID_ON_TIME | I8: =IF(H8="UNPAID", AsOfDate-D8, 0) | J8: =IF(F8<>"", TEXT(F8, "yyyy-mm"), "")
A9: RP0000008 | B9: LN200001 | C9: 8 | D9: 45944 | E9: 7793.5 | F9: 45947 | G9: 7793.5 | H9: PAID_ON_TIME | I9: =IF(H9="UNPAID", AsOfDate-D9, 0) | J9: =IF(F9<>"", TEXT(F9, "yyyy-mm"), "")
A10: RP0000009 | B10: LN200001 | C10: 9 | D10: 45975 | E10: 7793.5 | F10: 45978 | G10: 7793.5 | H10: PAID_ON_TIME | I10: =IF(H10="UNPAID", AsOfDate-D10, 0) | J10: =IF(F10<>"", TEXT(F10, "yyyy-mm"), "")
A11: RP0000010 | B11: LN200001 | C11: 10 | D11: 46005 | E11: 7793.5 | F11: 46003 | G11: 7793.5 | H11: PAID_ON_TIME | I11: =IF(H11="UNPAID", AsOfDate-D11, 0) | J11: =IF(F11<>"", TEXT(F11, "yyyy-mm"), "")
A12: RP0000011 | B12: LN200001 | C12: 11 | D12: 46036 | E12: 7793.5 | F12: 46035 | G12: 7793.5 | H12: PAID_ON_TIME | I12: =IF(H12="UNPAID", AsOfDate-D12, 0) | J12: =IF(F12<>"", TEXT(F12, "yyyy-mm"), "")
A13: RP0000012 | B13: LN200001 | C13: 12 | D13: 46067 | E13: 7793.5 | F13: 46069 | G13: 7793.5 | H13: PAID_ON_TIME | I13: =IF(H13="UNPAID", AsOfDate-D13, 0) | J13: =IF(F13<>"", TEXT(F13, "yyyy-mm"), "")
... A21: RP0000020 | B21: LN200003 | C21: 5 | D21: 46149 | E21: 19313.06 | F21: 46152 | G21: 19313.06 | H21: PAID_ON_TIME | I21: =IF(H21="UNPAID", AsOfDate-D21, 0) | J21: =IF(F21<>"", TEXT(F21, "yyyy-mm"), "")
A22: RP0000021 | B22: LN200003 | C22: 6 | D22: 46180 | E22: 19313.06 | G22: 0 | H22: UNPAID | I22: =IF(H22="UNPAID", AsOfDate-D22, 0) | J22: =IF(F22<>"", TEXT(F22, "yyyy-mm"), "")
A23: RP0000022 | B23: LN200003 | C23: 7 | D23: 46210 | E23: 19313.06 | F23: 46207 | G23: 19313.06 | H23: PAID_ON_TIME | I23: =IF(H23="UNPAID", AsOfDate-D23, 0) | J23: =IF(F23<>"", TEXT(F23, "yyyy-mm"), "")
A24: RP0000023 | B24: LN200003 | C24: 8 | D24: 46241 | E24: 19313.06 | F24: 46240 | G24: 19313.06 | H24: PAID_ON_TIME | I24: =IF(H24="UNPAID", AsOfDate-D24, 0) | J24: =IF(F24<>"", TEXT(F24, "yyyy-mm"), "")
A25: RP0000024 | B25: LN200003 | C25: 9 | D25: 46272 | E25: 19313.06 | G25: 0 | H25: NOT_DUE | I25: =IF(H25="UNPAID", AsOfDate-D25, 0) | J25: =IF(F25<>"", TEXT(F25, "yyyy-mm"), "")
A26: RP0000025 | B26: LN200003 | C26: 10 | D26: 46302 | E26: 19313.06 | G26: 0 | H26: NOT_DUE | I26: =IF(H26="UNPAID", AsOfDate-D26, 0) | J26: =IF(F26<>"", TEXT(F26, "yyyy-mm"), "")
A27: RP0000026 | B27: LN200003 | C27: 11 | D27: 46333 | E27: 19313.06 | G27: 0 | H27: NOT_DUE | I27: =IF(H27="UNPAID", AsOfDate-D27, 0) | J27: =IF(F27<>"", TEXT(F27, "yyyy-mm"), "")
A28: RP0000027 | B28: LN200003 | C28: 12 | D28: 46363 | E28: 19313.06 | G28: 0 | H28: NOT_DUE | I28: =IF(H28="UNPAID", AsOfDate-D28, 0) | J28: =IF(F28<>"", TEXT(F28, "yyyy-mm"), "")
A29: RP0000028 | B29: LN200003 | C29: 13 | D29: 46394 | E29: 19313.06 | G29: 0 | H29: NOT_DUE | I29: =IF(H29="UNPAID", AsOfDate-D29, 0) | J29: =IF(F29<>"", TEXT(F29, "yyyy-mm"), "")
A30: RP0000029 | B30: LN200003 | C30: 14 | D30: 46425 | E30: 19313.06 | G30: 0 | H30: NOT_DUE | I30: =IF(H30="UNPAID", AsOfDate-D30, 0) | J30: =IF(F30<>"", TEXT(F30, "yyyy-mm"), "")
A31: RP0000030 | B31: LN200003 | C31: 15 | D31: 46453 | E31: 19313.06 | G31: 0 | H31: NOT_DUE | I31: =IF(H31="UNPAID", AsOfDate-D31, 0) | J31: =IF(F31<>"", TEXT(F31, "yyyy-mm"), "")
A32: RP0000031 | B32: LN200003 | C32: 16 | D32: 46484 | E32: 19313.06 | G32: 0 | H32: NOT_DUE | I32: =IF(H32="UNPAID", AsOfDate-D32, 0) | J32: =IF(F32<>"", TEXT(F32, "yyyy-mm"), "")
A33: RP0000032 | B33: LN200003 | C33: 17 | D33: 46514 | E33: 19313.06 | G33: 0 | H33: NOT_DUE | I33: =IF(H33="UNPAID", AsOfDate-D33, 0) | J33: =IF(F33<>"", TEXT(F33, "yyyy-mm"), "")
A34: RP0000033 | B34: LN200003 | C34: 18 | D34: 46545 | E34: 19313.06 | G34: 0 | H34: NOT_DUE | I34: =IF(H34="UNPAID", AsOfDate-D34, 0) | J34: =IF(F34<>"", TEXT(F34, "yyyy-mm"), "")
A35: RP0000034 | B35: LN200004 | C35: 1 | D35: 46064 | E35: 12618 | F35: 46099 | G35: 12618 | H35: PAID_LATE | I35: =IF(H35="UNPAID", AsOfDate-D35, 0) | J35: =IF(F35<>"", TEXT(F35, "yyyy-mm"), "")
A36: RP0000035 | B36: LN200004 | C36: 2 | D36: 46092 | E36: 12618 | F36: 46112 | G36: 12618 | H36: PAID_LATE | I36: =IF(H36="UNPAID", AsOfDate-D36, 0) | J36: =IF(F36<>"", TEXT(F36, "yyyy-mm"), "")
A37: RP0000036 | B37: LN200004 | C37: 3 | D37: 46123 | E37: 12618 | F37: 46211 | G37: 12618 | H37: PAID_LATE | I37: =IF(H37="UNPAID", AsOfDate-D37, 0) | J37: =IF(F37<>"", TEXT(F37, "yyyy-mm"), "")
A38: RP0000037 | B38: LN200005 | C38: 1 | D38: 46050 | E38: 19231.33 | F38: 46121 | G38: 19231.33 | H38: PAID_LATE | I38: =IF(H38="UNPAID", AsOfDate-D38, 0) | J38: =IF(F38<>"", TEXT(F38, "yyyy-mm"), "")
A39: RP0000038 | B39: LN200005 | C39: 2 | D39: 46081 | E39: 19231.33 | F39: 46082 | G39: 19231.33 | H39: PAID_ON_TIME | I39: =IF(H39="UNPAID", AsOfDate-D39, 0) | J39: =IF(F39<>"", TEXT(F39, "yyyy-mm"), "")
A40: RP0000039 | B40: LN200005 | C40: 3 | D40: 46109 | E40: 19231.33 | F40: 46107 | G40: 19231.33 | H40: PAID_ON_TIME | I40: =IF(H40="UNPAID", AsOfDate-D40, 0) | J40: =IF(F40<>"", TEXT(F40, "yyyy-mm"), "")
A41: RP0000040 | B41: LN200006 | C41: 1 | D41: 45980 | E41: 145820.67 | F41: 45981 | G41: 145820.67 | H41: PAID_ON_TIME | I41: =IF(H41="UNPAID", AsOfDate-D41, 0) | J41: =IF(F41<>"", TEXT(F41, "yyyy-mm"), "")
A42: RP0000041 | B42: LN200006 | C42: 2 | D42: 46010 | E42: 145820.67 | F42: 46014 | G42: 145820.67 | H42: PAID_ON_TIME | I42: =IF(H42="UNPAID", AsOfDate-D42, 0) | J42: =IF(F42<>"", TEXT(F42, "yyyy-mm"), "")
A43: RP0000042 | B43: LN200006 | C43: 3 | D43: 46041 | E43: 145820.67 | F43: 46118 | G43: 145820.67 | H43: PAID_LATE | I43: =IF(H43="UNPAID", AsOfDate-D43, 0) | J43: =IF(F43<>"", TEXT(F43, "yyyy-mm"), "")
A44: RP0000043 | B44: LN200007 | C44: 1 | D44: 46189 | E44: 33009.67 | F44: 46193 | G44: 33009.67 | H44: PAID_ON_TIME | I44: =IF(H44="UNPAID", AsOfDate-D44, 0) | J44: =IF(F44<>"", TEXT(F44, "yyyy-mm"), "")
A45: RP0000044 | B45: LN200007 | C45: 2 | D45: 46219 | E45: 33009.67 | F45: 46221 | G45: 33009.67 | H45: PAID_ON_TIME | I45: =IF(H45="UNPAID", AsOfDate-D45, 0) | J45: =IF(F45<>"", TEXT(F45, "yyyy-mm"), "")
A46: RP0000045 | B46: LN200007 | C46: 3 | D46: 46250 | E46: 33009.67 | F46: 46253 | G46: 33009.67 | H46: PAID_ON_TIME | I46: =IF(H46="UNPAID", AsOfDate-D46, 0) | J46: =IF(F46<>"", TEXT(F46, "yyyy-mm"), "")
A47: RP0000046 | B47: LN200007 | C47: 4 | D47: 46281 | E47: 33009.67 | G47: 0 | H47: NOT_DUE | I47: =IF(H47="UNPAID", AsOfDate-D47, 0) | J47: =IF(F47<>"", TEXT(F47, "yyyy-mm"), "")
...
